<?xml version="1.0" encoding="utf-8"?>
<!-- This URDF was automatically created by SolidWorks to URDF Exporter! Originally created by Stephen Brawner (brawner@gmail.com) 
     Commit Version: 1.6.0-4-g7f85cfe  Build Version: 1.6.7995.38578
     For more information, please see http://wiki.ros.org/sw_urdf_exporter -->
<robot
  name="Full_Assembly">
  <link
    name="Chassis_Frame">
    <inertial>
      <origin
        xyz="0.019745 -0.0030165 0.68744"
        rpy="0 0 0" />
      <mass
        value="16.261" />
      <inertia
        ixx="0.13729"
        ixy="5.7892E-06"
        ixz="8.1421E-07"
        iyy="0.28071"
        iyz="1.9925E-06"
        izz="0.19755" />
    </inertial>
    <visual>
      <origin
        xyz="0 0 0"
        rpy="0 0 0" />
      <geometry>
        <mesh
          filename="package://rover_description/meshes/base_link.STL" />
      </geometry>
      <material
        name="">
        <color
          rgba="0.79216 0.81961 0.93333 1" />
      </material>
    </visual>
    <collision>
      <origin
        xyz="0 0 0"
        rpy="0 0 0" />
      <geometry>
        <mesh
          filename="package://rover_description/meshes/base_link.STL" />
      </geometry>
    </collision>
  </link>
  <link
    name="Left_Bogie">
    <inertial>
      <origin
        xyz="0.0073281 0.26318 -0.17042"
        rpy="0 0 0" />
      <mass
        value="3.3412" />
      <inertia
        ixx="0.0081828"
        ixy="8.0231E-09"
        ixz="8.4738E-11"
        iyy="0.0056985"
        iyz="0.0010554"
        izz="0.0069193" />
    </inertial>
    <visual>
      <origin
        xyz="0 0 0"
        rpy="0 0 0" />
      <geometry>
        <mesh
          filename="package://rover_description/meshes/Left_Bogie.STL" />
      </geometry>
      <material
        name="">
        <color
          rgba="0.79216 0.81961 0.93333 1" />
      </material>
    </visual>
    <collision>
      <origin
        xyz="0 0 0"
        rpy="0 0 0" />
      <geometry>
        <mesh
          filename="package://rover_description/meshes/Left_Bogie.STL" />
      </geometry>
    </collision>
  </link>
  <joint
    name="Left_Connect"
    type="fixed">
    <origin
      xyz="-0.3042 -0.049685 -0.1836"
      rpy="0.51305 0 3.1416" />
    <parent
      link="Chassis_Frame" />
    <child
      link="Left_Bogie" />
    <axis
      xyz="0 0.87125 -0.49083" />
    <limit
      lower="0"
      upper="0"
      effort="0"
      velocity="0" />
  </joint>
  <link
    name="Left_Bogie_Front_Wheel">
    <inertial>
      <origin
        xyz="0.130564845809255 0.0138364458137181 0.0507999999999999"
        rpy="0 0 0" />
      <mass
        value="4.54890356187038" />
      <inertia
        ixx="0.0201202982558325"
        ixy="4.33680868994202E-19"
        ixz="-7.49449804390759E-19"
        iyy="0.0201202982558325"
        iyz="3.12256934504413E-18"
        izz="0.0324145415197282" />
    </inertial>
    <visual>
      <origin
        xyz="0 0 0"
        rpy="0 0 0" />
      <geometry>
        <mesh
          filename="package://rover_description/meshes/Left_Bogie_Front_Wheel.STL" />
      </geometry>
      <material
        name="">
        <color
          rgba="0.792156862745098 0.819607843137255 0.933333333333333 1" />
      </material>
    </visual>
    <collision>
      <origin
        xyz="0 0 0"
        rpy="0 0 0" />
      <geometry>
        <mesh
          filename="package://rover_description/meshes/Left_Bogie_Front_Wheel.STL" />
      </geometry>
    </collision>
  </link>
  <joint
    name="Left_Connect_Front"
    type="continuous">
    <origin
      xyz="0.082925 -0.074392 -0.045555"
      rpy="1.5708 0.61863 1.5708" />
    <parent
      link="Left_Bogie" />
    <child
      link="Left_Bogie_Front_Wheel" />
    <axis
      xyz="0.99443 0.10538 0" />
    <limit
      lower="0"
      upper="0"
      effort="0"
      velocity="0" />
  </joint>
  <link
    name="Left_Bogie_Back_Wheel">
    <inertial>
      <origin
        xyz="0.11938 -5.55111512312578E-17 -0.0508000000000001"
        rpy="0 0 0" />
      <mass
        value="4.54890356187038" />
      <inertia
        ixx="0.0201202982558325"
        ixy="-1.37812516427891E-33"
        ixz="7.34366271496856E-19"
        iyy="0.0201202982558325"
        iyz="3.09652182247156E-18"
        izz="0.0324145415197282" />
    </inertial>
    <visual>
      <origin
        xyz="0 0 0"
        rpy="0 0 0" />
      <geometry>
        <mesh
          filename="package://rover_description/meshes/Left_Bogie_Back_Wheel.STL" />
      </geometry>
      <material
        name="">
        <color
          rgba="0.792156862745098 0.819607843137255 0.933333333333333 1" />
      </material>
    </visual>
    <collision>
      <origin
        xyz="0 0 0"
        rpy="0 0 0" />
      <geometry>
        <mesh
          filename="package://rover_description/meshes/Left_Bogie_Back_Wheel.STL" />
      </geometry>
    </collision>
  </link>
  <joint
    name="Left_Connect_Back"
    type="continuous">
    <origin
      xyz="0.082925 0.32306 -0.27488"
      rpy="-1.5708 0.51305 1.5708" />
    <parent
      link="Left_Bogie" />
    <child
      link="Left_Bogie_Back_Wheel" />
    <axis
      xyz="1 0 0" />
    <limit
      lower="0"
      upper="0"
      effort="0"
      velocity="0" />
  </joint>
  <link
    name="Right_Bogie">
    <inertial>
      <origin
        xyz="-0.313254747777612 -0.18264536433249 0.0354994663678213"
        rpy="0 0 0" />
      <mass
        value="3.34124121849343" />
      <inertia
        ixx="0.00508994978325339"
        ixy="2.4814466779376E-05"
        ixz="6.9485935182769E-09"
        iyy="0.00752780533653533"
        iyz="4.01185960582563E-09"
        izz="0.0081827901963465" />
    </inertial>
    <visual>
      <origin
        xyz="0 0 0"
        rpy="0 0 0" />
      <geometry>
        <mesh
          filename="package://rover_description/meshes/Right_Bogie.STL" />
      </geometry>
      <material
        name="">
        <color
          rgba="0.752941176470588 0.752941176470588 0.752941176470588 1" />
      </material>
    </visual>
    <collision>
      <origin
        xyz="0 0 0"
        rpy="0 0 0" />
      <geometry>
        <mesh
          filename="package://rover_description/meshes/Right_Bogie.STL" />
      </geometry>
    </collision>
  </link>
  <joint
    name="Right_Connect"
    type="fixed">
    <origin
      xyz="0.3105 -0.053202 -0.020263"
      rpy="1.5708 0 1.5708" />
    <parent
      link="Chassis_Frame" />
    <child
      link="Right_Bogie" />
    <axis
      xyz="1 0 0" />
    <limit
      lower="0"
      upper="0"
      effort="0"
      velocity="0" />
  </joint>
  <link
    name="Right_Bogie_Front_Wheel">
    <inertial>
      <origin
        xyz="-0.0904301784153555 5.55111512312578E-17 0.0508000000000001"
        rpy="0 0 0" />
      <mass
        value="4.54890356187038" />
      <inertia
        ixx="0.0201202982558325"
        ixy="-4.89110791271853E-33"
        ixz="-7.34366271496863E-19"
        iyy="0.0201202982558325"
        iyz="1.27619897151731E-17"
        izz="0.0324145415197282" />
    </inertial>
    <visual>
      <origin
        xyz="0 0 0"
        rpy="0 0 0" />
      <geometry>
        <mesh
          filename="package://rover_description/meshes/Right_Bogie_Front_Wheel.STL" />
      </geometry>
      <material
        name="">
        <color
          rgba="0.792156862745098 0.819607843137255 0.933333333333333 1" />
      </material>
    </visual>
    <collision>
      <origin
        xyz="0 0 0"
        rpy="0 0 0" />
      <geometry>
        <mesh
          filename="package://rover_description/meshes/Right_Bogie_Front_Wheel.STL" />
      </geometry>
    </collision>
  </link>
  <joint
    name="Right_Connect_Front"
    type="continuous">
    <origin
      xyz="0 -0.24426 0.1111"
      rpy="0 0 0" />
    <parent
      link="Right_Bogie" />
    <child
      link="Right_Bogie_Front_Wheel" />
    <axis
      xyz="1 0 0" />
    <limit
      lower="0"
      upper="0"
      effort="0"
      velocity="0" />
  </joint>
  <link
    name="Right_Bogie_Back_Wheel">
    <inertial>
      <origin
        xyz="-0.130564845809256 -0.013836445813718 0.0508"
        rpy="0 0 0" />
      <mass
        value="4.54890356187038" />
      <inertia
        ixx="0.0201202982558325"
        ixy="4.33680868994202E-19"
        ixz="-2.06450675522236E-18"
        iyy="0.0201202982558325"
        iyz="1.26266851207273E-17"
        izz="0.0324145415197282" />
    </inertial>
    <visual>
      <origin
        xyz="0 0 0"
        rpy="0 0 0" />
      <geometry>
        <mesh
          filename="package://rover_description/meshes/Right_Bogie_Back_Wheel.STL" />
      </geometry>
      <material
        name="">
        <color
          rgba="0.792156862745098 0.819607843137255 0.933333333333333 1" />
      </material>
    </visual>
    <collision>
      <origin
        xyz="0 0 0"
        rpy="0 0 0" />
      <geometry>
        <mesh
          filename="package://rover_description/meshes/Right_Bogie_Back_Wheel.STL" />
      </geometry>
    </collision>
  </link>
  <joint
    name="Right_Connect_Back"
    type="continuous">
    <origin
      xyz="-0.40606 -0.23955 0.1111"
      rpy="0 0 -0.10558" />
    <parent
      link="Right_Bogie" />
    <child
      link="Right_Bogie_Back_Wheel" />
    <axis
      xyz="0.99443 0.10538 0" />
    <limit
      lower="0"
      upper="0"
      effort="0"
      velocity="0" />
  </joint>
  <link
    name="Back_Bogie">
    <inertial>
      <origin
        xyz="-0.000289279887737415 0.063617383840847 -0.0148260057036792"
        rpy="0 0 0" />
      <mass
        value="2.03126342918492" />
      <inertia
        ixx="0.0076939410308437"
        ixy="-1.47557141759034E-05"
        ixz="-6.6684282943255E-09"
        iyy="0.00629537083030239"
        iyz="2.25382545207914E-08"
        izz="0.00234582536528961" />
    </inertial>
    <visual>
      <origin
        xyz="0 0 0"
        rpy="0 0 0" />
      <geometry>
        <mesh
          filename="package://rover_description/meshes/Back_Bogie.STL" />
      </geometry>
      <material
        name="">
        <color
          rgba="0.792156862745098 0.819607843137255 0.933333333333333 1" />
      </material>
    </visual>
    <collision>
      <origin
        xyz="0 0 0"
        rpy="0 0 0" />
      <geometry>
        <mesh
          filename="package://rover_description/meshes/Back_Bogie.STL" />
      </geometry>
    </collision>
  </link>
  <joint
    name="Back_Connect"
    type="fixed">
    <origin
      xyz="0 -0.93191 -0.25941"
      rpy="1.5602 -0.010551 -1.5707" />
    <parent
      link="Chassis_Frame" />
    <child
      link="Back_Bogie" />
    <axis
      xyz="0.00011134 0.010551 -0.99994" />
    <limit
      lower="0"
      upper="0"
      effort="0"
      velocity="0" />
  </joint>
  <link
    name="Back_Bogie_Left_Wheel">
    <inertial>
      <origin
        xyz="-1.14531348801572E-05 -0.00108536680223514 -0.0520615041256314"
        rpy="0 0 0" />
      <mass
        value="4.54890356187038" />
      <inertia
        ixx="0.0201202982558325"
        ixy="-5.42101086242752E-20"
        ixz="-1.75552403538904E-17"
        iyy="0.0201202982558325"
        iyz="-1.1895911365396E-17"
        izz="0.0324145415197282" />
    </inertial>
    <visual>
      <origin
        xyz="0 0 0"
        rpy="0 0 0" />
      <geometry>
        <mesh
          filename="package://rover_description/meshes/Back_Bogie_Left_Wheel.STL" />
      </geometry>
      <material
        name="">
        <color
          rgba="0.792156862745098 0.819607843137255 0.933333333333333 1" />
      </material>
    </visual>
    <collision>
      <origin
        xyz="0 0 0"
        rpy="0 0 0" />
      <geometry>
        <mesh
          filename="package://rover_description/meshes/Back_Bogie_Left_Wheel.STL" />
      </geometry>
    </collision>
  </link>
  <joint
    name="Back_Connect_Left"
    type="continuous">
    <origin
      xyz="0 -0.00069199 0.32718"
      rpy="3.1416 0 3.1205" />
    <parent
      link="Back_Bogie" />
    <child
      link="Back_Bogie_Left_Wheel" />
    <axis
      xyz="0.00011134 0.010551 0.99994" />
    <limit
      lower="0"
      upper="0"
      effort="0"
      velocity="0" />
  </joint>
  <link
    name="Back_Bogie_Right_Wheel">
    <inertial>
      <origin
        xyz="-1.11022302462516E-16 -0.00108528771922412 0.0520482833385267"
        rpy="0 0 0" />
      <mass
        value="4.54890356187038" />
      <inertia
        ixx="0.0201202982558325"
        ixy="-1.56128184385634E-21"
        ixz="6.18841737345298E-18"
        iyy="0.0201202982558325"
        iyz="1.35498166506376E-16"
        izz="0.0324145415197282" />
    </inertial>
    <visual>
      <origin
        xyz="0 0 0"
        rpy="0 0 0" />
      <geometry>
        <mesh
          filename="package://rover_description/meshes/Back_Bogie_Right_Wheel.STL" />
      </geometry>
      <material
        name="">
        <color
          rgba="0.792156862745098 0.819607843137255 0.933333333333333 1" />
      </material>
    </visual>
    <collision>
      <origin
        xyz="0 0 0"
        rpy="0 0 0" />
      <geometry>
        <mesh
          filename="package://rover_description/meshes/Back_Bogie_Right_Wheel.STL" />
      </geometry>
    </collision>
  </link>
  <joint
    name="Back_Connect_Right"
    type="continuous">
    <origin
      xyz="-3.0207E-05 -0.0028626 -0.35685"
      rpy="3.1416 0 -0.010552" />
    <parent
      link="Back_Bogie" />
    <child
      link="Back_Bogie_Right_Wheel" />
    <axis
      xyz="0 0.010552 -0.99994" />
  </joint>
  <link
    name="Arm">
    <inertial>
      <origin
        xyz="-0.0477985055997259 -0.0352326124467943 0.00312955608244202"
        rpy="0 0 0" />
      <mass
        value="0.232083853065316" />
      <inertia
        ixx="0.000808900388660283"
        ixy="-0.00045117057053435"
        ixz="3.23063350248503E-19"
        iyy="0.00108878956515546"
        iyz="2.88580132867235E-19"
        izz="0.0018961637397099" />
    </inertial>
    <visual>
      <origin
        xyz="0 0 0"
        rpy="0 0 0" />
      <geometry>
        <mesh
          filename="package://rover_description/meshes/Arm.STL" />
      </geometry>
      <material
        name="">
        <color
          rgba="0.792156862745098 0.819607843137255 0.933333333333333 1" />
      </material>
    </visual>
    <collision>
      <origin
        xyz="0 0 0"
        rpy="0 0 0" />
      <geometry>
        <mesh
          filename="package://rover_description/meshes/Arm.STL" />
      </geometry>
    </collision>
  </link>
  <joint
    name="Arm"
    type="fixed">
    <origin
      xyz="0.017177 -0.37345 0.064678"
      rpy="-3.1416 0 2.2059" />
    <parent
      link="Chassis_Frame" />
    <child
      link="Arm" />
    <axis
      xyz="0 0 0" />
  </joint>
  <link
    name="Axis_1">
    <inertial>
      <origin
        xyz="0.00533143411780451 -0.00443747075635542 0.0621628028964215"
        rpy="0 0 0" />
      <mass
        value="0.806942884675543" />
      <inertia
        ixx="0.000915177079263181"
        ixy="0.000130358110680842"
        ixz="-5.27078323383203E-05"
        iyy="0.000834903089479575"
        iyz="7.02912626220492E-05"
        izz="0.00094963789281678" />
    </inertial>
    <visual>
      <origin
        xyz="0 0 0"
        rpy="0 0 0" />
      <geometry>
        <mesh
          filename="package://rover_description/meshes/Axis_1.STL" />
      </geometry>
      <material
        name="">
        <color
          rgba="0.752941176470588 0.752941176470588 0.752941176470588 1" />
      </material>
    </visual>
    <collision>
      <origin
        xyz="0 0 0"
        rpy="0 0 0" />
      <geometry>
        <mesh
          filename="package://rover_description/meshes/Axis_1.STL" />
      </geometry>
    </collision>
  </link>
  <joint
    name="J1"
    type="continuous">
    <origin
      xyz="0 0.01 0"
      rpy="3.1416 0 -0.15031" />
    <parent
      link="Arm" />
    <child
      link="Axis_1" />
    <axis
      xyz="0 0 0" />
  </joint>
  <link
    name="Axis_2">
    <inertial>
      <origin
        xyz="-0.0792879650387348 -0.0374774475075469 -0.00119909962756731"
        rpy="0 0 0" />
      <mass
        value="1.11833636541395" />
      <inertia
        ixx="0.0112903031926762"
        ixy="4.91795053354935E-06"
        ixz="9.59984967509602E-07"
        iyy="0.00141194104590659"
        iyz="7.46219989748416E-06"
        izz="0.0110197921139019" />
    </inertial>
    <visual>
      <origin
        xyz="0 0 0"
        rpy="0 0 0" />
      <geometry>
        <mesh
          filename="package://rover_description/meshes/Axis_2.STL" />
      </geometry>
      <material
        name="">
        <color
          rgba="0.792156862745098 0.819607843137255 0.933333333333333 1" />
      </material>
    </visual>
    <collision>
      <origin
        xyz="0 0 0"
        rpy="0 0 0" />
      <geometry>
        <mesh
          filename="package://rover_description/meshes/Axis_2.STL" />
      </geometry>
    </collision>
  </link>
  <joint
    name="J2"
    type="continuous">
    <origin
      xyz="0.1255 -0.050208 0.25442"
      rpy="2.1053 0 0.63509" />
    <parent
      link="Axis_1" />
    <child
      link="Axis_2" />
    <axis
      xyz="0 0 0" />
  </joint>
  <link
    name="Axis_3">
    <inertial>
      <origin
        xyz="-0.177860531990118 -0.229002221909752 -0.168526766868434"
        rpy="0 0 0" />
      <mass
        value="0.315238010654722" />
      <inertia
        ixx="0.000287891199207417"
        ixy="2.11380283665009E-05"
        ixz="-1.05853873569157E-06"
        iyy="0.000297440212924729"
        iyz="-2.52338452951327E-06"
        izz="0.000181117976352556" />
    </inertial>
    <visual>
      <origin
        xyz="0 0 0"
        rpy="0 0 0" />
      <geometry>
        <mesh
          filename="package://rover_description/meshes/Axis_3.STL" />
      </geometry>
      <material
        name="">
        <color
          rgba="0.792156862745098 0.819607843137255 0.933333333333333 1" />
      </material>
    </visual>
    <collision>
      <origin
        xyz="0 0 0"
        rpy="0 0 0" />
      <geometry>
        <mesh
          filename="package://rover_description/meshes/Axis_3.STL" />
      </geometry>
    </collision>
  </link>
  <joint
    name="J3"
    type="continuous">
    <origin
      xyz="-0.23569 -0.087829 -0.0037519"
      rpy="1.5708 0.89688 -1.5708" />
    <parent
      link="Axis_2" />
    <child
      link="Axis_3" />
    <axis
      xyz="0 0 0" />
  </joint>
  <link
    name="Axis_4">
    <inertial>
      <origin
        xyz="-0.000728157152736608 0.000525658570672105 0.175741311829104"
        rpy="0 0 0" />
      <mass
        value="1.04432383241743" />
      <inertia
        ixx="0.00525323858585558"
        ixy="3.11334770659038E-05"
        ixz="6.58925562122348E-06"
        iyy="0.00527392420385386"
        iyz="-4.75671087351871E-06"
        izz="0.00131026306361566" />
    </inertial>
    <visual>
      <origin
        xyz="0 0 0"
        rpy="0 0 0" />
      <geometry>
        <mesh
          filename="package://rover_description/meshes/Axis_4.STL" />
      </geometry>
      <material
        name="">
        <color
          rgba="0.792156862745098 0.819607843137255 0.933333333333333 1" />
      </material>
    </visual>
    <collision>
      <origin
        xyz="0 0 0"
        rpy="0 0 0" />
      <geometry>
        <mesh
          filename="package://rover_description/meshes/Axis_4.STL" />
      </geometry>
    </collision>
  </link>
  <joint
    name="J4"
    type="continuous">
    <origin
      xyz="-0.19367 -0.18832 -0.1742"
      rpy="1.5708 0.94291 -2.2385" />
    <parent
      link="Axis_3" />
    <child
      link="Axis_4" />
    <axis
      xyz="0 0 0" />
  </joint>
  <link
    name="Axis_5">
    <inertial>
      <origin
        xyz="-0.0102060777999421 0.0299772381028147 0.0283371876416308"
        rpy="0 0 0" />
      <mass
        value="0.292157049786524" />
      <inertia
        ixx="0.000350020526589252"
        ixy="4.61969257518864E-05"
        ixz="1.55314231304865E-06"
        iyy="0.000251179817698524"
        iyz="-3.34039930499824E-06"
        izz="0.000356943911820366" />
    </inertial>
    <visual>
      <origin
        xyz="0 0 0"
        rpy="0 0 0" />
      <geometry>
        <mesh
          filename="package://rover_description/meshes/Axis_5.STL" />
      </geometry>
      <material
        name="">
        <color
          rgba="0.792156862745098 0.819607843137255 0.933333333333333 1" />
      </material>
    </visual>
    <collision>
      <origin
        xyz="0 0 0"
        rpy="0 0 0" />
      <geometry>
        <mesh
          filename="package://rover_description/meshes/Axis_5.STL" />
      </geometry>
    </collision>
  </link>
  <joint
    name="J5"
    type="continuous">
    <origin
      xyz="-0.026332 0.019007 0.43639"
      rpy="-1.5708 0.078756 -2.196" />
    <parent
      link="Axis_4" />
    <child
      link="Axis_5" />
    <axis
      xyz="0 0 0" />
  </joint>
  <link
    name="Axis_6">
    <inertial>
      <origin
        xyz="0.032926652089996 0.00543778249297716 0.0226168399991655"
        rpy="0 0 0" />
      <mass
        value="0.150772297399764" />
      <inertia
        ixx="0.000139664763970518"
        ixy="5.12145203214631E-07"
        ixz="8.22255437779973E-08"
        iyy="0.00013880534583195"
        iyz="4.83939019279555E-07"
        izz="6.09308789523862E-05" />
    </inertial>
    <visual>
      <origin
        xyz="0 0 0"
        rpy="0 0 0" />
      <geometry>
        <mesh
          filename="package://rover_description/meshes/Axis_6.STL" />
      </geometry>
      <material
        name="">
        <color
          rgba="0.792156862745098 0.819607843137255 0.933333333333333 1" />
      </material>
    </visual>
    <collision>
      <origin
        xyz="0 0 0"
        rpy="0 0 0" />
      <geometry>
        <mesh
          filename="package://rover_description/meshes/Axis_6.STL" />
      </geometry>
    </collision>
  </link>
  <joint
    name="J6"
    type="continuous">
    <origin
      xyz="0 0 0"
      rpy="1.5708 -1.3993 0.37994" />
    <parent
      link="Axis_5" />
    <child
      link="Axis_6" />
    <axis
      xyz="0 0 0" />
  </joint>
</robot>