<?xml version="1.0"?>
<robot name="simple_2dof_arm">
  <!-- Base Link -->
  <link name="base_link">
    <visual>
      <geometry>
        <cylinder length="0.1" radius="0.1"/>
      </geometry>
    </visual>
  </link>

  <!-- Link 1 -->
  <link name="link1">
    <visual>
      <geometry>
        <cylinder length="1.0" radius="0.05"/>
      </geometry>
    </visual>
  </link>

  <!-- Link 2 -->
  <link name="link2">
    <visual>
      <geometry>
        <cylinder length="1.0" radius="0.05"/>
      </geometry>
    </visual>
  </link>

  <!-- Joint 1 -->
  <joint name="joint1" type="revolute">
    <parent link="base_link"/>
    <child link="link1"/>
    <origin xyz="0 0 0.55" rpy="0 0 0"/>
    <axis xyz="0 0 1"/>
    <limit lower="-1.5707" upper="1.5707" effort="50.0" velocity="1.0"/>
  </joint>

  <!-- Joint 2 -->
  <joint name="joint2" type="revolute">
    <parent link="link1"/>
    <child link="link2"/>
    <origin xyz="0.0 0 1.05" rpy="0 0 0"/>
    <axis xyz="0 0 1"/>
    <limit lower="-1.5707" upper="1.5707" effort="50.0" velocity="1.0"/>
  </joint>
</robot>
