<?xml version="1.0" encoding="utf-8"?>
<!-- This URDF was automatically created by SolidWorks to URDF Exporter! Originally created by Stephen Brawner (brawner@gmail.com) 
     Commit Version: 1.6.0-4-g7f85cfe  Build Version: 1.6.7995.38578
     For more information, please see http://wiki.ros.org/sw_urdf_exporter -->
<robot
  name="arm1">
  <link
    name="base_link">
    <inertial>
      <origin
        xyz="-0.75118 -0.35506 0.6181"
        rpy="0 0 0" />
      <mass
        value="0.48809" />
      <inertia
        ixx="0.0015559"
        ixy="-0.00029123"
        ixz="-2.6469E-05"
        iyy="0.0011495"
        iyz="-0.00059278"
        izz="0.0016056" />
    </inertial>
    <visual>
      <origin
        xyz="0 0 0"
        rpy="0 0 0" />
      <geometry>
        <mesh
          filename="package://arm1/meshes/base_link.STL" />
      </geometry>
      <material
        name="">
        <color
          rgba="0.62745 0.65882 0.67843 1" />
      </material>
    </visual>
    <collision>
      <origin
        xyz="0 0 0"
        rpy="0 0 0" />
      <geometry>
        <mesh
          filename="package://arm1/meshes/base_link.STL" />
      </geometry>
    </collision>
  </link>
  <link
    name="link_turntable">
    <inertial>
      <origin
        xyz="-0.025587 -0.012115 0.041225"
        rpy="0 0 0" />
      <mass
        value="0.83487" />
      <inertia
        ixx="0.00094597"
        ixy="-4.0179E-05"
        ixz="-5.1927E-05"
        iyy="0.0010583"
        iyz="4.635E-06"
        izz="0.00071889" />
    </inertial>
    <visual>
      <origin
        xyz="0 0 0"
        rpy="0 0 0" />
      <geometry>
        <mesh
          filename="package://arm1/meshes/link_turntable.STL" />
      </geometry>
      <material
        name="">
        <color
          rgba="0.89804 0.91765 0.92941 1" />
      </material>
    </visual>
    <collision>
      <origin
        xyz="0 0 0"
        rpy="0 0 0" />
      <geometry>
        <mesh
          filename="package://arm1/meshes/link_turntable.STL" />
      </geometry>
    </collision>
  </link>
  <joint
    name="joint_turntable"
    type="continuous">
    <origin
      xyz="-0.75729581407264 -0.598615888399153 -0.307790852884674"
      rpy="0 0 -1.5707963267949" />
    <parent
      link="base_link" />
    <child
      link="link_turntable" />
    <axis
      xyz="0.751654206505026 0.300853226584914 -0.586944026204157" />
  </joint>
  <link
    name="link_axis1">
    <inertial>
      <origin
        xyz="-0.026363 -0.11844 0.13898"
        rpy="0 0 0" />
      <mass
        value="1.2075" />
      <inertia
        ixx="0.0099183"
        ixy="-0.00074072"
        ixz="0.0031258"
        iyy="0.011079"
        iyz="0.0016509"
        izz="0.00304" />
    </inertial>
    <visual>
      <origin
        xyz="0 0 0"
        rpy="0 0 0" />
      <geometry>
        <mesh
          filename="package://arm1/meshes/link_axis1.STL" />
      </geometry>
      <material
        name="">
        <color
          rgba="0.75294 0.75294 0.75294 1" />
      </material>
    </visual>
    <collision>
      <origin
        xyz="0 0 0"
        rpy="0 0 0" />
      <geometry>
        <mesh
          filename="package://arm1/meshes/link_axis1.STL" />
      </geometry>
    </collision>
  </link>
  <joint
    name="joint_axis1"
    type="continuous">
    <origin
      xyz="-0.0655207637557417 0.0577180534779368 0.0734579500015488"
      rpy="0 0 0" />
    <parent
      link="link_turntable" />
    <child
      link="link_axis1" />
    <axis
      xyz="0.328543830326874 -0.942430072702363 -0.0623258342933837" />
  </joint>
  <link
    name="link_axis2">
    <inertial>
      <origin
        xyz="0.0120616928967049 -0.0575161563291976 0.00362961179898152"
        rpy="0 0 0" />
      <mass
        value="0.50949002444583" />
      <inertia
        ixx="0.000489832647698887"
        ixy="7.26871784681246E-05"
        ixz="-9.41603824346971E-06"
        iyy="0.000311727928592659"
        iyz="-2.03565135651366E-05"
        izz="0.000545866848612843" />
    </inertial>
    <visual>
      <origin
        xyz="0 0 0"
        rpy="0 0 0" />
      <geometry>
        <mesh
          filename="package://arm1/meshes/link_axis2.STL" />
      </geometry>
      <material
        name="">
        <color
          rgba="0.752941176470588 0.752941176470588 0.752941176470588 1" />
      </material>
    </visual>
    <collision>
      <origin
        xyz="0 0 0"
        rpy="0 0 0" />
      <geometry>
        <mesh
          filename="package://arm1/meshes/link_axis2.STL" />
      </geometry>
    </collision>
  </link>
  <joint
    name="joint_axis2"
    type="continuous">
    <origin
      xyz="-0.119315742016965 -0.0911363032403798 0.328341244367117"
      rpy="0 0 0" />
    <parent
      link="link_axis1" />
    <child
      link="link_axis2" />
    <axis
      xyz="0.328543830326874 -0.942430072702362 -0.062325834293384" />
  </joint>
  <link
    name="link_axis3">
    <inertial>
      <origin
        xyz="0.213335533760281 0.0695601801859741 0.098443768367438"
        rpy="0 0 0" />
      <mass
        value="0.881583524101265" />
      <inertia
        ixx="0.00207559183419843"
        ixy="-0.000914107654223854"
        ixz="-0.00138374507363724"
        iyy="0.00468849837599157"
        iyz="-0.000446845064746683"
        izz="0.00446997979885745" />
    </inertial>
    <visual>
      <origin
        xyz="0 0 0"
        rpy="0 0 0" />
      <geometry>
        <mesh
          filename="package://arm1/meshes/link_axis3.STL" />
      </geometry>
      <material
        name="">
        <color
          rgba="0.627450980392157 0.658823529411765 0.67843137254902 1" />
      </material>
    </visual>
    <collision>
      <origin
        xyz="0 0 0"
        rpy="0 0 0" />
      <geometry>
        <mesh
          filename="package://arm1/meshes/link_axis3.STL" />
      </geometry>
    </collision>
  </link>
  <joint
    name="joint_axis3"
    type="continuous">
    <origin
      xyz="0.018218 -0.048216 -0.0027262"
      rpy="0 0 0" />
    <parent
      link="link_axis2" />
    <child
      link="link_axis3" />
    <axis
      xyz="-0.87281 -0.27773 -0.40132" />
  </joint>
  <link
    name="link_axis4">
    <inertial>
      <origin
        xyz="2.21515842878661E-05 -0.0468597309294064 -0.00242519114267015"
        rpy="0 0 0" />
      <mass
        value="0.39169705426019" />
      <inertia
        ixx="0.000306613917411435"
        ixy="-5.47499906973088E-05"
        ixz="8.55743025528078E-06"
        iyy="0.000454493934676782"
        iyz="2.29987326931141E-06"
        izz="0.000482222947756292" />
    </inertial>
    <visual>
      <origin
        xyz="0 0 0"
        rpy="0 0 0" />
      <geometry>
        <mesh
          filename="package://arm1/meshes/link_axis4.STL" />
      </geometry>
      <material
        name="">
        <color
          rgba="0.627450980392157 0.658823529411765 0.67843137254902 1" />
      </material>
    </visual>
    <collision>
      <origin
        xyz="0 0 0"
        rpy="0 0 0" />
      <geometry>
        <mesh
          filename="package://arm1/meshes/link_axis4.STL" />
      </geometry>
    </collision>
  </link>
  <joint
    name="joint_axis4"
    type="continuous">
    <origin
      xyz="0.39197 0.16869 0.18931"
      rpy="0 0 0" />
    <parent
      link="link_axis3" />
    <child
      link="link_axis4" />
    <axis
      xyz="0.3295 -0.94193 -0.064754" />
  </joint>
  <link
    name="link_ender">
    <inertial>
      <origin
        xyz="-0.0362253408744452 -0.0127905539174791 0.00171737280923212"
        rpy="0 0 0" />
      <mass
        value="0.0496523692311761" />
      <inertia
        ixx="7.69610493253832E-06"
        ixy="-5.82800269092538E-06"
        ixz="7.8745024704373E-07"
        iyy="2.21461021933751E-05"
        iyz="2.77743045115595E-07"
        izz="2.41638018238003E-05" />
    </inertial>
    <visual>
      <origin
        xyz="0 0 0"
        rpy="0 0 0" />
      <geometry>
        <mesh
          filename="package://arm1/meshes/link_ender.STL" />
      </geometry>
      <material
        name="">
        <color
          rgba="0.627450980392157 0.658823529411765 0.67843137254902 1" />
      </material>
    </visual>
    <collision>
      <origin
        xyz="0 0 0"
        rpy="0 0 0" />
      <geometry>
        <mesh
          filename="package://arm1/meshes/link_ender.STL" />
      </geometry>
    </collision>
  </link>
  <joint
    name="joint_ender"
    type="continuous">
    <origin
      xyz="0.069889 -0.019771 -0.0053796"
      rpy="0 0 0" />
    <parent
      link="link_axis4" />
    <child
      link="link_ender" />
    <axis
      xyz="-0.94201 -0.3326 0.044705" />
  </joint>
</robot>