<?xml version="1.0" encoding="utf-8" ?>
<!-- This URDF was automatically created by SolidWorks to URDF Exporter! Originally created by Stephen Brawner (brawner@gmail.com) 
     Commit Version: 1.6.0-4-g7f85cfe  Build Version: 1.6.7995.38578
     For more information, please see http://wiki.ros.org/sw_urdf_exporter -->
<robot name="snowbots_arm_urdf_simplified_v5_12">
<!-- <joint name="j1" type="continuous">
        <origin xyz="-0.16681 -0.11566 0.018262" rpy="0 0 0" />
        <parent link="world" />
        <child link="l2" />
        <axis xyz="0 0 1" />
    </joint> -->
<link name="world">
</link>
<joint name="world_joint" type="fixed">
        <origin xyz="0.0 0.0 1.09" rpy="0 0 0" />
        <parent link="world" />
        <child link="l1" />
         <axis xyz="0 0 1" /> 
    </joint>  
    <link name="l1">
        <inertial>
            <origin xyz="-0.168479827162396 -0.115656336839165 0.00578093326197773" rpy="0 0 0" />
            <mass value="0.733491685538154" />
            <inertia ixx="0.00196115627924208" ixy="0.0001" ixz="0.0001" iyy="0.001877726034367" iyz="0.0001" izz="0.00376586973501081" />
        </inertial>
        <visual>
            <origin xyz="0 0 0" rpy="0 0 0" />
            <geometry>
                <mesh filename="package://snowbots_arm_urdf_simplified_v5_12/meshes/l1.STL" />
            </geometry>
            <material name="">
                <color rgba="0.752941176470588 0.752941176470588 0.752941176470588 1" />
            </material>
        </visual>
        <collision>
            <origin xyz="0 0 0" rpy="0 0 0" />
            <geometry>
                <mesh filename="package://snowbots_arm_urdf_simplified_v5_12/meshes/l1.STL" />
            </geometry>
        </collision>
    </link>
    <link name="l2">
        <inertial>
            <origin xyz="-0.00223967300075031 0.0 0.0102631542786473" rpy="0 0 0" />
            <mass value="0.250775647780571" />
            <inertia ixx="0.000537910808454074" ixy="0.0001" ixz="0.000258073706594528" iyy="0.000436108333138116" iyz="0.0001" izz="0.000869807679942593" />
        </inertial>
        <visual>
            <origin xyz="0 0 0" rpy="0 0 0" />
            <geometry>
                <mesh filename="package://snowbots_arm_urdf_simplified_v5_12/meshes/l2.STL" />
            </geometry>
            <material name="">
                <color rgba="0.752941176470588 0.752941176470588 0.752941176470588 1" />
            </material>
        </visual>
        <collision>
            <origin xyz="0 0 0" rpy="0 0 0" />
            <geometry>
                <mesh filename="package://snowbots_arm_urdf_simplified_v5_12/meshes/l2.STL" />
            </geometry>
        </collision>
    </link>
    <joint name="j1" type="continuous">
        <origin xyz="-0.16681 -0.11566 0.018262" rpy="0 0 0" />
        <parent link="l1" />
        <child link="l2" />
        <axis xyz="0 0 1" />
    </joint>
    <link name="l3">
        <inertial>
            <origin xyz="0.0004 0.0239245727073928 0.0" rpy="0 0 0" />
            <mass value="0.102884531575438" />
            <inertia ixx="0.00879556882291034" ixy="0.0001" ixz="0.0001" iyy="0.00261900523250968" iyz="0.0001" izz="0.00766388032777999" />
        </inertial><gazebo>
    <isStatic>true</isStatic>
</gazebo>
        <visual>
            <origin xyz="0 0 0" rpy="0 0 0" />
            <geometry>
                <mesh filename="package://snowbots_arm_urdf_simplified_v5_12/meshes/l3.STL" />
            </geometry>
            <material name="">
                <color rgba="0.752941176470588 0.752941176470588 0.752941176470588 1" />
            </material>
        </visual>
        <collision>
            <origin xyz="0 0 0" rpy="0 0 0" />
            <geometry>
                <mesh filename="package://snowbots_arm_urdf_simplified_v5_12/meshes/l3.STL" />
            </geometry>
        </collision>
    </link>
    <joint name="j2" type="continuous">
        <origin xyz="0.03025 0 0.08135" rpy="1.5708 0 3.1416" />
        <parent link="l2" />
        <child link="l3" />
        <axis xyz="0 0 1" />
    </joint>
    <link name="l4">
        <inertial>
            <origin xyz="0.00226816102522268 0.0 1.65251658703902E-05" rpy="0 0 0" />
            <mass value="1.08198232148716" />
            <inertia ixx="0.0021829023488644" ixy="0.0001" ixz="0.0001" iyy="0.00220354743226762" iyz="0.0001" izz="0.00142067321575571" />
        </inertial>
        <visual>
            <origin xyz="0 0 0" rpy="0 0 0" />
            <geometry>
                <mesh filename="package://snowbots_arm_urdf_simplified_v5_12/meshes/l4.STL" />
            </geometry>
            <material name="">
                <color rgba="0.752941176470588 0.752941176470588 0.752941176470588 1" />
            </material>
        </visual>
        <collision>
            <origin xyz="0 0 0" rpy="0 0 0" />
            <geometry>
                <mesh filename="package://snowbots_arm_urdf_simplified_v5_12/meshes/l4.STL" />
            </geometry>
        </collision>
    </link>
<joint name="j3" type="revolute">
    <origin xyz="0 0.36 0" rpy="0 0 3.1416" />
    <parent link="l3" />
    <child link="l4" />
    <axis xyz="0 0 -1" />
    <limit lower="-1.13446" upper="1.13446" effort="30.0" velocity="1.0"/>
</joint>

    <link name="l5">
        <inertial>
            <origin xyz="0.0 0.0 -0.133249135431632" rpy="0 0 0" />
            <mass value="1.33086052072626" />
            <inertia ixx="0.00895840763765954" ixy="0.0001" ixz="0.0001" iyy="0.00873704695466796" iyz="0.0001" izz="0.00133806494519881" />
        </inertial>
        <visual>
            <origin xyz="0 0 0" rpy="0 0 0" />
            <geometry>
                <mesh filename="package://snowbots_arm_urdf_simplified_v5_12/meshes/l5.STL" />
            </geometry>
            <material name="">
                <color rgba="0.752941176470588 0.752941176470588 0.752941176470588 1" />
            </material>
        </visual>
        <collision>
            <origin xyz="0 0 0" rpy="0 0 0" />
            <geometry>
                <mesh filename="package://snowbots_arm_urdf_simplified_v5_12/meshes/l5.STL" />
            </geometry>
        </collision>
    </link>
    <joint name="j4" type="continuous">
        <origin xyz="0.05 0 0" rpy="-1.5708 0 1.5708" />
        <parent link="l4" />
        <child link="l5" />
        <axis xyz="0 0 -1" />
    </joint>
    <link name="l6">
        <inertial>
            <origin xyz="0.00199123381435215 0.0 0.0" rpy="0 0 0" />
            <mass value="0.492952229102601" />
            <inertia ixx="0.000719349317967228" ixy="0.0001" ixz="0.0001" iyy="0.000329383302634573" iyz="0.0001" izz="0.000732786626667122" />
        </inertial>
        <visual>
            <origin xyz="0 0 0" rpy="0 0 0" />
            <geometry>
                <mesh filename="package://snowbots_arm_urdf_simplified_v5_12/meshes/l6.STL" />
            </geometry>
            <material name="">
                <color rgba="0.752941176470588 0.752941176470588 0.752941176470588 1" />
            </material>
        </visual>
        <collision>
            <origin xyz="0 0 0" rpy="0 0 0" />
            <geometry>
                <mesh filename="package://snowbots_arm_urdf_simplified_v5_12/meshes/l6.STL" />
            </geometry>
        </collision>
    </link>
    <joint name="j5" type="continuous">
        <origin xyz="0 0 -0.334" rpy="3.1416 1.5708 0" />
        <parent link="l5" />
        <child link="l6" />
        <axis xyz="0 1 0" />
    </joint>
    <link name="l7">
        <inertial>
            <origin xyz="0 0.00266488951978006 0.005" rpy="0 0 0" />
            <mass value="0.0374663749693614" />
            <inertia ixx="1.29723066499449E-05" ixy="0.00001" ixz="0.0001" iyy="1.57184875775034E-05" iyz="0.0001" izz="0.0001" />
        </inertial>
        <visual>
            <origin xyz="0 0 0" rpy="0 0 0" />
            <geometry>
                <mesh filename="package://snowbots_arm_urdf_simplified_v5_12/meshes/l7.STL" />
            </geometry>
            <material name="">
                <color rgba="0.752941176470588 0.752941176470588 0.752941176470588 1" />
            </material>
        </visual>
        <collision>
            <origin xyz="0 0 0" rpy="0 0 0" />
            <geometry>
                <mesh filename="package://snowbots_arm_urdf_simplified_v5_12/meshes/l7.STL" />
            </geometry>
        </collision>
    </link>
    <joint name="j6" type="continuous">
        <origin xyz="0.0378 0 0" rpy="1.5708 0 1.5708" />
        <parent link="l6" />
        <child link="l7" />
        <axis xyz="0 0 1" />
    </joint>
    <link name="ef">
        <inertial>
            <origin xyz="0.0 0.0 -0.0898279852825325" rpy="0 0 0" />
            <mass value="0.11427222801809" />
            <inertia ixx="0.0" ixy="0.0001" ixz="0.0001" iyy="7.71894569292431E-05" iyz="0.0001" izz="0.00303303765648842" />
        </inertial>
        <visual>
            <origin xyz="0 0 0" rpy="0 0 0" />
            <geometry>
                <mesh filename="package://snowbots_arm_urdf_simplified_v5_12/meshes/ef.STL" />
            </geometry>
            <material name="">
                <color rgba="0.752941176470588 0.752941176470588 0.752941176470588 1" />
            </material>
        </visual>
        <collision>
            <origin xyz="0 0 0" rpy="0 0 0" />
            <geometry>
                <mesh filename="package://snowbots_arm_urdf_simplified_v5_12/meshes/ef.STL" />
            </geometry>
        </collision>
    </link>
    <joint name="j7" type="fixed">
        <origin xyz="0 0 0.12886" rpy="0 0 3.1416" />
        <parent link="l7" />
        <child link="ef" />
        <!-- <axis xyz="0 0 0" /> -->
    </joint>
    <joint name="camera_joint" type="fixed">
  <origin xyz="0 0 0.2" rpy="0 0 1"/>
  <parent link="ef"/>
  <child link="camera_link"/>
</joint>

<link name="camera_link">
  <inertial>
    <mass value="0.1"/>
    <inertia ixx="1.0" ixy="0.0" ixz="0.0" iyy="1.0" iyz="0.0" izz="1.0"/>
  </inertial>
</link>

    <transmission name="trans_j1">
        <type>transmission_interface/SimpleTransmission</type>
        <joint name="j1">
            <hardwareInterface>hardware_interface/PositionJointInterface</hardwareInterface>
            <!-- only one hardware interface is currently supported, the easiest way to change is just ctrl F. Effort works the best, position kind of works but gives errors, velocity is untested -->
        </joint>
        <actuator name="j1_motor">
            <!-- <hardwareInterface>hardware_interface/PositionJointInterface</hardwareInterface> -->
            <mechanicalReduction>1</mechanicalReduction>
        </actuator>
    </transmission>
    <transmission name="trans_j2">
        <type>transmission_interface/SimpleTransmission</type>
        <joint name="j2">
            <hardwareInterface>hardware_interface/PositionJointInterface</hardwareInterface>
        </joint>
        <actuator name="j2_motor">
            <!-- <hardwareInterface>hardware_interface/PositionJointInterface</hardwareInterface> -->
            <mechanicalReduction>1</mechanicalReduction>
        </actuator>
    </transmission>
    <transmission name="trans_j3">
        <type>transmission_interface/SimpleTransmission</type>
        <joint name="j3">
            <hardwareInterface>hardware_interface/PositionJointInterface</hardwareInterface>
        </joint>
        <actuator name="j3_motor">
            <!-- <hardwareInterface>hardware_interface/PositionJointInterface</hardwareInterface> -->
            <mechanicalReduction>1</mechanicalReduction>
        </actuator>
    </transmission>
    <transmission name="trans_j4">
        <type>transmission_interface/SimpleTransmission</type>
        <joint name="j4">
            <hardwareInterface>hardware_interface/PositionJointInterface</hardwareInterface>
        </joint>
        <actuator name="j4_motor">
            <!-- <hardwareInterface>hardware_interface/PositionJointInterface</hardwareInterface> -->
            <mechanicalReduction>1</mechanicalReduction>
        </actuator>
    </transmission>
    <transmission name="trans_j5">
        <type>transmission_interface/SimpleTransmission</type>
        <joint name="j5">
            <hardwareInterface>hardware_interface/PositionJointInterface</hardwareInterface>
        </joint>
        <actuator name="j5_motor">
            <!-- <hardwareInterface>hardware_interface/PositionJointInterface</hardwareInterface> -->
            <mechanicalReduction>1</mechanicalReduction>
        </actuator>
    </transmission>
    <transmission name="trans_j6">
        <type>transmission_interface/SimpleTransmission</type>
        <joint name="j6">
            <hardwareInterface>hardware_interface/PositionJointInterface</hardwareInterface>
        </joint>
        <actuator name="j6_motor">
            <!-- <hardwareInterface>hardware_interface/PositionJointInterface</hardwareInterface> -->
            <mechanicalReduction>1</mechanicalReduction>
        </actuator>
    </transmission>
    <gazebo>
  <plugin name="gazebo_ros_control" filename="libgazebo_ros_control.so">
    <!-- <robotNamespace>/snowbots_arm_urdf_simplified_v5_12</robotNamespace> -->
  </plugin>
    </gazebo>
    <gazebo reference="camera_link">
  <sensor type="camera" name="camera_sensor">
    <update_rate>30.0</update_rate>
    <camera name="head">
      <horizontal_fov>1.3962634</horizontal_fov>
      <image>
        <width>800</width>
        <height>800</height>
        <format>R8G8B8</format>
      </image>
      <clip>
        <near>0.02</near>
        <far>300</far>
      </clip>
    </camera>
    <plugin name="camera_controller" filename="libgazebo_ros_camera.so">
      <alwaysOn>true</alwaysOn>
      <updateRate>0.0</updateRate>
      <cameraName>robot/camera</cameraName>
      <imageTopicName>image_raw</imageTopicName>
      <cameraInfoTopicName>camera_info</cameraInfoTopicName>
      <frameName>camera_link</frameName>
    </plugin>
  </sensor>
</gazebo>

</robot>

